[2023-09-05 22:57:56,770] ERROR log_exception() L1449 Exception on /por-categoria [POST] - call_trace=C:\Users\Robson\OneDrive\Documentos\PUC\SPRINT_1\MVP\meu_app_api\venv\lib\site-packages\flask\app.py L1449
Traceback (most recent call last):
  File "C:\Users\Robson\OneDrive\Documentos\PUC\SPRINT_1\MVP\meu_app_api\venv\lib\site-packages\flask\app.py", line 2073, in wsgi_app
    response = self.full_dispatch_request()
  File "C:\Users\Robson\OneDrive\Documentos\PUC\SPRINT_1\MVP\meu_app_api\venv\lib\site-packages\flask\app.py", line 1519, in full_dispatch_request
    rv = self.handle_user_exception(e)
  File "C:\Users\Robson\OneDrive\Documentos\PUC\SPRINT_1\MVP\meu_app_api\venv\lib\site-packages\flask_cors\extension.py", line 165, in wrapped_function
    return cors_after_request(app.make_response(f(*args, **kwargs)))
  File "C:\Users\Robson\OneDrive\Documentos\PUC\SPRINT_1\MVP\meu_app_api\venv\lib\site-packages\flask\app.py", line 1517, in full_dispatch_request
    rv = self.dispatch_request()
  File "C:\Users\Robson\OneDrive\Documentos\PUC\SPRINT_1\MVP\meu_app_api\venv\lib\site-packages\flask\app.py", line 1503, in dispatch_request
    return self.ensure_sync(self.view_functions[rule.endpoint])(**req.view_args)
  File "C:\Users\Robson\OneDrive\Documentos\PUC\SPRINT_1\MVP\meu_app_api\venv\lib\site-packages\flask_openapi3\scaffold.py", line 191, in wrapper
    resp = _do_wrapper(
  File "C:\Users\Robson\OneDrive\Documentos\PUC\SPRINT_1\MVP\meu_app_api\venv\lib\site-packages\flask_openapi3\do_wrapper.py", line 135, in _do_wrapper
    response = func(**request_kwargs)
  File "C:\Users\Robson\OneDrive\Documentos\PUC\SPRINT 3\COMPONENTE C\meu_app_api\app.py", line 297, in get_consultaPorCategoria
    return {"historicos": apresenta_historicos(categorias)}, 200
  File "C:\Users\Robson\OneDrive\Documentos\PUC\SPRINT 3\COMPONENTE C\meu_app_api\schemas\historico.py", line 39, in apresenta_historicos
    return [apresenta_historico(historico) for historico in historicos]
  File "C:\Users\Robson\OneDrive\Documentos\PUC\SPRINT 3\COMPONENTE C\meu_app_api\schemas\historico.py", line 39, in <listcomp>
    return [apresenta_historico(historico) for historico in historicos]
  File "C:\Users\Robson\OneDrive\Documentos\PUC\SPRINT 3\COMPONENTE C\meu_app_api\schemas\historico.py", line 34, in apresenta_historico
    "nome": historico.usuario_obj.nome
AttributeError: 'NoneType' object has no attribute 'nome'
[2023-09-05 22:57:56,866] INFO _log() L224  127.0.0.1 - - [05/Sep/2023 22:57:56] "[35m[1mPOST /por-categoria HTTP/1.1[0m" 500 - - call_trace=C:\Users\Robson\OneDrive\Documentos\PUC\SPRINT_1\MVP\meu_app_api\venv\lib\site-packages\werkzeug\_internal.py L224 
[2023-09-05 22:58:00,183] INFO _log() L224  127.0.0.1 - - [05/Sep/2023 22:58:00] "OPTIONS /por-usuario HTTP/1.1" 200 - - call_trace=C:\Users\Robson\OneDrive\Documentos\PUC\SPRINT_1\MVP\meu_app_api\venv\lib\site-packages\werkzeug\_internal.py L224 
[2023-09-05 22:58:00,201] INFO _log() L224  127.0.0.1 - - [05/Sep/2023 22:58:00] "POST /por-usuario HTTP/1.1" 200 - - call_trace=C:\Users\Robson\OneDrive\Documentos\PUC\SPRINT_1\MVP\meu_app_api\venv\lib\site-packages\werkzeug\_internal.py L224 
[2023-09-05 22:58:02,957] INFO _log() L224  127.0.0.1 - - [05/Sep/2023 22:58:02] "OPTIONS /por-categoria HTTP/1.1" 200 - - call_trace=C:\Users\Robson\OneDrive\Documentos\PUC\SPRINT_1\MVP\meu_app_api\venv\lib\site-packages\werkzeug\_internal.py L224 
[2023-09-05 22:58:02,971] ERROR log_exception() L1449 Exception on /por-categoria [POST] - call_trace=C:\Users\Robson\OneDrive\Documentos\PUC\SPRINT_1\MVP\meu_app_api\venv\lib\site-packages\flask\app.py L1449
Traceback (most recent call last):
  File "C:\Users\Robson\OneDrive\Documentos\PUC\SPRINT_1\MVP\meu_app_api\venv\lib\site-packages\flask\app.py", line 2073, in wsgi_app
    response = self.full_dispatch_request()
  File "C:\Users\Robson\OneDrive\Documentos\PUC\SPRINT_1\MVP\meu_app_api\venv\lib\site-packages\flask\app.py", line 1519, in full_dispatch_request
    rv = self.handle_user_exception(e)
  File "C:\Users\Robson\OneDrive\Documentos\PUC\SPRINT_1\MVP\meu_app_api\venv\lib\site-packages\flask_cors\extension.py", line 165, in wrapped_function
    return cors_after_request(app.make_response(f(*args, **kwargs)))
  File "C:\Users\Robson\OneDrive\Documentos\PUC\SPRINT_1\MVP\meu_app_api\venv\lib\site-packages\flask\app.py", line 1517, in full_dispatch_request
    rv = self.dispatch_request()
  File "C:\Users\Robson\OneDrive\Documentos\PUC\SPRINT_1\MVP\meu_app_api\venv\lib\site-packages\flask\app.py", line 1503, in dispatch_request
    return self.ensure_sync(self.view_functions[rule.endpoint])(**req.view_args)
  File "C:\Users\Robson\OneDrive\Documentos\PUC\SPRINT_1\MVP\meu_app_api\venv\lib\site-packages\flask_openapi3\scaffold.py", line 191, in wrapper
    resp = _do_wrapper(
  File "C:\Users\Robson\OneDrive\Documentos\PUC\SPRINT_1\MVP\meu_app_api\venv\lib\site-packages\flask_openapi3\do_wrapper.py", line 135, in _do_wrapper
    response = func(**request_kwargs)
  File "C:\Users\Robson\OneDrive\Documentos\PUC\SPRINT 3\COMPONENTE C\meu_app_api\app.py", line 297, in get_consultaPorCategoria
    return {"historicos": apresenta_historicos(categorias)}, 200
  File "C:\Users\Robson\OneDrive\Documentos\PUC\SPRINT 3\COMPONENTE C\meu_app_api\schemas\historico.py", line 39, in apresenta_historicos
    return [apresenta_historico(historico) for historico in historicos]
  File "C:\Users\Robson\OneDrive\Documentos\PUC\SPRINT 3\COMPONENTE C\meu_app_api\schemas\historico.py", line 39, in <listcomp>
    return [apresenta_historico(historico) for historico in historicos]
  File "C:\Users\Robson\OneDrive\Documentos\PUC\SPRINT 3\COMPONENTE C\meu_app_api\schemas\historico.py", line 34, in apresenta_historico
    "nome": historico.usuario_obj.nome
AttributeError: 'NoneType' object has no attribute 'nome'
[2023-09-05 22:58:02,981] INFO _log() L224  127.0.0.1 - - [05/Sep/2023 22:58:02] "[35m[1mPOST /por-categoria HTTP/1.1[0m" 500 - - call_trace=C:\Users\Robson\OneDrive\Documentos\PUC\SPRINT_1\MVP\meu_app_api\venv\lib\site-packages\werkzeug\_internal.py L224 
[2023-09-05 22:58:07,088] ERROR log_exception() L1449 Exception on /por-categoria [POST] - call_trace=C:\Users\Robson\OneDrive\Documentos\PUC\SPRINT_1\MVP\meu_app_api\venv\lib\site-packages\flask\app.py L1449
Traceback (most recent call last):
  File "C:\Users\Robson\OneDrive\Documentos\PUC\SPRINT_1\MVP\meu_app_api\venv\lib\site-packages\flask\app.py", line 2073, in wsgi_app
    response = self.full_dispatch_request()
  File "C:\Users\Robson\OneDrive\Documentos\PUC\SPRINT_1\MVP\meu_app_api\venv\lib\site-packages\flask\app.py", line 1519, in full_dispatch_request
    rv = self.handle_user_exception(e)
  File "C:\Users\Robson\OneDrive\Documentos\PUC\SPRINT_1\MVP\meu_app_api\venv\lib\site-packages\flask_cors\extension.py", line 165, in wrapped_function
    return cors_after_request(app.make_response(f(*args, **kwargs)))
  File "C:\Users\Robson\OneDrive\Documentos\PUC\SPRINT_1\MVP\meu_app_api\venv\lib\site-packages\flask\app.py", line 1517, in full_dispatch_request
    rv = self.dispatch_request()
  File "C:\Users\Robson\OneDrive\Documentos\PUC\SPRINT_1\MVP\meu_app_api\venv\lib\site-packages\flask\app.py", line 1503, in dispatch_request
    return self.ensure_sync(self.view_functions[rule.endpoint])(**req.view_args)
  File "C:\Users\Robson\OneDrive\Documentos\PUC\SPRINT_1\MVP\meu_app_api\venv\lib\site-packages\flask_openapi3\scaffold.py", line 191, in wrapper
    resp = _do_wrapper(
  File "C:\Users\Robson\OneDrive\Documentos\PUC\SPRINT_1\MVP\meu_app_api\venv\lib\site-packages\flask_openapi3\do_wrapper.py", line 135, in _do_wrapper
    response = func(**request_kwargs)
  File "C:\Users\Robson\OneDrive\Documentos\PUC\SPRINT 3\COMPONENTE C\meu_app_api\app.py", line 297, in get_consultaPorCategoria
    return {"historicos": apresenta_historicos(categorias)}, 200
  File "C:\Users\Robson\OneDrive\Documentos\PUC\SPRINT 3\COMPONENTE C\meu_app_api\schemas\historico.py", line 39, in apresenta_historicos
    return [apresenta_historico(historico) for historico in historicos]
  File "C:\Users\Robson\OneDrive\Documentos\PUC\SPRINT 3\COMPONENTE C\meu_app_api\schemas\historico.py", line 39, in <listcomp>
    return [apresenta_historico(historico) for historico in historicos]
  File "C:\Users\Robson\OneDrive\Documentos\PUC\SPRINT 3\COMPONENTE C\meu_app_api\schemas\historico.py", line 34, in apresenta_historico
    "nome": historico.usuario_obj.nome
AttributeError: 'NoneType' object has no attribute 'nome'
[2023-09-05 22:58:07,109] INFO _log() L224  127.0.0.1 - - [05/Sep/2023 22:58:07] "[35m[1mPOST /por-categoria HTTP/1.1[0m" 500 - - call_trace=C:\Users\Robson\OneDrive\Documentos\PUC\SPRINT_1\MVP\meu_app_api\venv\lib\site-packages\werkzeug\_internal.py L224 
[2023-09-05 22:59:10,381] INFO _log() L224   * Running on all addresses (0.0.0.0)
   WARNING: This is a development server. Do not use it in a production deployment.
 * Running on http://127.0.0.1:5000
 * Running on http://10.0.0.229:5000 (Press CTRL+C to quit) - call_trace=C:\Users\Robson\OneDrive\Documentos\PUC\SPRINT_1\MVP\meu_app_api\venv\lib\site-packages\werkzeug\_internal.py L224 
[2023-09-05 22:59:11,662] INFO _log() L224  127.0.0.1 - - [05/Sep/2023 22:59:11] "OPTIONS /por-categoria HTTP/1.1" 200 - - call_trace=C:\Users\Robson\OneDrive\Documentos\PUC\SPRINT_1\MVP\meu_app_api\venv\lib\site-packages\werkzeug\_internal.py L224 
